[2024-04-01 15:13:39,309] {taskinstance.py:1179} INFO - Dependencies all met for <TaskInstance: Lead_scoring_training_pipeline.encoding_categorical_variables scheduled__2024-03-01T00:00:00+00:00 [queued]>
[2024-04-01 15:13:39,314] {taskinstance.py:1179} INFO - Dependencies all met for <TaskInstance: Lead_scoring_training_pipeline.encoding_categorical_variables scheduled__2024-03-01T00:00:00+00:00 [queued]>
[2024-04-01 15:13:39,314] {taskinstance.py:1376} INFO - 
--------------------------------------------------------------------------------
[2024-04-01 15:13:39,314] {taskinstance.py:1377} INFO - Starting attempt 2 of 2
[2024-04-01 15:13:39,314] {taskinstance.py:1378} INFO - 
--------------------------------------------------------------------------------
[2024-04-01 15:13:39,334] {taskinstance.py:1397} INFO - Executing <Task(PythonOperator): encoding_categorical_variables> on 2024-03-01 00:00:00+00:00
[2024-04-01 15:13:39,342] {standard_task_runner.py:52} INFO - Started process 6252 to run task
[2024-04-01 15:13:39,346] {standard_task_runner.py:79} INFO - Running: ['airflow', 'tasks', 'run', 'Lead_scoring_training_pipeline', 'encoding_categorical_variables', 'scheduled__2024-03-01T00:00:00+00:00', '--job-id', '32', '--raw', '--subdir', 'DAGS_FOLDER/lead_scoring_training_pipeline/.ipynb_checkpoints/lead_scoring_training_pipeline-checkpoint.py', '--cfg-path', '/tmp/tmprvbnj7lf', '--error-file', '/tmp/tmpxej50kzf']
[2024-04-01 15:13:39,347] {standard_task_runner.py:80} INFO - Job 32: Subtask encoding_categorical_variables
[2024-04-01 15:13:39,394] {task_command.py:371} INFO - Running <TaskInstance: Lead_scoring_training_pipeline.encoding_categorical_variables scheduled__2024-03-01T00:00:00+00:00 [running]> on host ac2457c935b6
[2024-04-01 15:13:39,486] {taskinstance.py:1589} INFO - Exporting the following env vars:
AIRFLOW_CTX_DAG_OWNER=airflow
AIRFLOW_CTX_DAG_ID=Lead_scoring_training_pipeline
AIRFLOW_CTX_TASK_ID=encoding_categorical_variables
AIRFLOW_CTX_EXECUTION_DATE=2024-03-01T00:00:00+00:00
AIRFLOW_CTX_TRY_NUMBER=2
AIRFLOW_CTX_DAG_RUN_ID=scheduled__2024-03-01T00:00:00+00:00
[2024-04-01 15:13:39,490] {logging_mixin.py:115} INFO - Loading model_input table
[2024-04-01 15:13:39,490] {taskinstance.py:1909} ERROR - Task failed with exception
Traceback (most recent call last):
  File "/opt/conda/lib/python3.8/site-packages/pandas/io/sql.py", line 2020, in execute
    cur.execute(*args, **kwargs)
sqlite3.OperationalError: no such table: model_input

The above exception was the direct cause of the following exception:

Traceback (most recent call last):
  File "/opt/conda/lib/python3.8/site-packages/airflow/operators/python.py", line 171, in execute
    return_value = self.execute_callable()
  File "/opt/conda/lib/python3.8/site-packages/airflow/operators/python.py", line 189, in execute_callable
    return self.python_callable(*self.op_args, **self.op_kwargs)
  File "/home/airflow/dags/lead_scoring_training_pipeline/utils.py", line 102, in encode_features
    df = pd.read_sql("select * from model_input", cnx)
  File "/opt/conda/lib/python3.8/site-packages/pandas/io/sql.py", line 566, in read_sql
    return pandas_sql.read_query(
  File "/opt/conda/lib/python3.8/site-packages/pandas/io/sql.py", line 2080, in read_query
    cursor = self.execute(*args)
  File "/opt/conda/lib/python3.8/site-packages/pandas/io/sql.py", line 2032, in execute
    raise ex from exc
pandas.io.sql.DatabaseError: Execution failed on sql 'select * from model_input': no such table: model_input
[2024-04-01 15:13:39,494] {taskinstance.py:1415} INFO - Marking task as FAILED. dag_id=Lead_scoring_training_pipeline, task_id=encoding_categorical_variables, execution_date=20240301T000000, start_date=20240401T151339, end_date=20240401T151339
[2024-04-01 15:13:39,515] {standard_task_runner.py:92} ERROR - Failed to execute job 32 for task encoding_categorical_variables (Execution failed on sql 'select * from model_input': no such table: model_input; 6252)
[2024-04-01 15:13:39,556] {local_task_job.py:156} INFO - Task exited with return code 1
[2024-04-01 15:13:39,619] {local_task_job.py:273} INFO - 0 downstream tasks scheduled from follow-on schedule check
